#VRML_SIM R2022a utf8
WorldInfo {
  info [
    "Example use of a color Camera device with recognition capability."
  ]
  title "Camera Image Recognition"
}
Viewpoint {
  orientation 0.4230646872725633 -0.029951437962670063 -0.9056043185337272 3.0485443866044966
  position 1.457257424142112 0.1382764770695935 1.5513929722001025
}
TexturedBackground {
}
TexturedBackgroundLight {
}
RectangleArena {
  floorSize 1.5 1.5
}
Can {
  translation 0.267626 0.290201 0.06096190081871349
  rotation -0.8823407580827052 -0.47014036099684875 -0.021043469005607638 8.45659060133885e-17
}
Can {
  translation -0.326272 -0.341474 0.06096190081871349
  rotation -0.8823407580827052 -0.47014036099684875 -0.021043469005607638 8.45659060133885e-17
  name "can(1)"
}
Apple {
  translation -0.260886 0.22946 0.049764745061238
  rotation 0 1 0 0
}
Apple {
  translation -0.621889 0.56252 0.049764745061238
  rotation 0 1 0 0
  name "apple(1)"
}
DEF ORANGE Solid {
  translation -0.002188 -0.063045 0
  children [
    Orange {
      translation -0.187654 0.182317 0.04999764793150722
      rotation 0 1 0 0
    }
  ]
  name "orange"
  recognitionColors [
    0.988235 0.686275 0.243137
  ]
}
DEF ORANGE Solid {
  translation 0.085807 -0.503005 0
  children [
    Orange {
      translation -0.187654 0.182317 0.04999764793150722
      rotation 0 1 0 0
    }
  ]
  name "orange(1)"
  recognitionColors [
    0.988235 0.686275 0.243137
  ]
}
JamJar {
  translation -0.33681 0.078775 0
  mass 0
}
JamJar {
  translation 0.314033 -0.288298 0
  rotation 0 0 1 2.094395
  name "jam jar(1)"
  mass 0
}
CerealBox {
  translation -0.43865 0.194464 -0.0003920931982210607
  rotation 7.672131713183349e-17 7.128580961901547e-17 -1 0.523599
}
CerealBox {
  translation -0.45025899348281107 0.41529999585090943 -0.00039220694597741357
  rotation -7.438330797950161e-08 -2.0088280332138234e-06 -0.9999999999979794 0.7853985634923097
  name "cereal box(1)"
}
OilBarrel {
  translation -0.28712 -0.211927 0.07
  rotation 0 0 1 -1.5707953071795862
  height 0.14
  radius 0.06
}
OilBarrel {
  translation -0.240466 -0.485864 0.07
  rotation 0 0 1 -1.5707953071795862
  name "oil barrel(1)"
  height 0.14
  radius 0.06
}
OilBarrel {
  translation -0.464787 -0.437183 0.07
  rotation 0 0 1 -1.5707953071795862
  name "oil barrel(2)"
  height 0.14
  radius 0.06
}
BiscuitBox {
  translation 0.5384121770599436 -0.27466816841412345 0.03984308800740198
  rotation 0.6947462352857392 -0.1861561094679343 -0.694747127711986 -2.773493129695837
}
RubberDuck {
  translation -0.243817 0.384468 0.020436910949152138
  rotation 8.636487449720478e-19 8.72526086072641e-18 1 -2.356195307179586
}
Robot {
  translation 0.08371810479804564 0.0005746534028056292 -0.0002342372045842228
  rotation 0.01389312527012053 -0.1879042664193337 -0.9820890833990777 -0.15033865103255994
  children [
    Transform {
      translation 0 0 0.0415
      children [
        Shape {
          appearance PBRAppearance {
            baseColor 0.0820075 0.364731 0.8
            roughness 1
            metalness 0
          }
          geometry DEF BODY Cylinder {
            height 0.08
            radius 0.045
          }
        }
      ]
    }
    HingeJoint {
      jointParameters HingeJointParameters {
        position -8.831797442806579
        axis 0 1 0
        anchor 0 0 0.025
      }
      device [
        RotationalMotor {
          name "left wheel motor"
          consumptionFactor 70
        }
        PositionSensor {
          name "left wheel sensor"
        }
      ]
      endPoint Solid {
        translation 0 0.045000000000000005 0.025
        rotation 0 -0.9999999999999999 0 1.2500968284474065
        children [
          DEF WHEEL Transform {
            rotation -1 0 0 1.57
            children [
              Shape {
                appearance PBRAppearance {
                  baseColor 1 0 0
                  roughness 1
                  metalness 0
                }
                geometry Cylinder {
                  height 0.01
                  radius 0.025
                }
              }
            ]
          }
        ]
        name "left wheel"
        boundingObject USE WHEEL
        physics DEF PHYSICS_WHEEL Physics {
          density -1
          mass 0.05
        }
        linearVelocity -0.03347560387407554 -0.004572112756240688 -8.97604900842737e-07
        angularVelocity 0.20168356105006863 -1.4865775880716146 0.759009837802324
      }
    }
    HingeJoint {
      jointParameters HingeJointParameters {
        position 8.831795780468491
        axis 0 1 0
        anchor 0 0 0.025
      }
      device [
        RotationalMotor {
          name "right wheel motor"
          consumptionFactor 70
        }
        PositionSensor {
          name "right wheel sensor"
        }
      ]
      endPoint Solid {
        translation 0 -0.045 0.025
        rotation 0 0.9999999999999999 0 4.244445780468491
        children [
          USE WHEEL
        ]
        name "right wheel"
        boundingObject USE WHEEL
        physics USE PHYSICS_WHEEL
        linearVelocity 0.033940129199167925 0.0045709307474333365 -8.617244662903769e-07
        angularVelocity -0.20166007990866064 1.4863791845263332 0.7590121725575337
      }
    }
    DistanceSensor {
      translation 0.042 0.02 0.063
      rotation 0 0 -1 -0.499205
      children [
        DEF SENSOR Transform {
          rotation 0 1 0 1.57
          children [
            Shape {
              appearance PBRAppearance {
                baseColor 0.975691 0.981481 0.0252992
                roughness 1
                metalness 0
              }
              geometry Cylinder {
                height 0.004
                radius 0.008
              }
            }
          ]
        }
      ]
      name "ds0"
      lookupTable [
        0 1024 0
        0.05 1024 0
        0.15 0 0
      ]
      numberOfRays 2
      aperture 1
    }
    DistanceSensor {
      translation 0.042 -0.02 0.063
      rotation 0 0 1 -0.500795
      children [
        USE SENSOR
      ]
      name "ds1"
      lookupTable [
        0 1024 0
        0.05 1024 0
        0.15 0 0
      ]
      numberOfRays 2
      aperture 1
    }
    Shape {
      appearance PBRAppearance {
        baseColor 0.8 0.8 0.8
        baseColorMap ImageTexture {
          url [
            "https://raw.githubusercontent.com/cyberbotics/webots/R2022a/projects/samples/devices/worlds/textures/mybot.png"
          ]
        }
        roughness 0.5
        metalness 0
      }
      geometry IndexedFaceSet {
        coord Coordinate {
          point [
            0.041 -0.015 0.038
            0.041 -0.015 0.023
            0.0455 0 0.023
            0.041 0.015 0.023
            0.041 0.015 0.038
            0.0455 0 0.038
          ]
        }
        texCoord TextureCoordinate {
          point [
            0 0
            0.5 0
            1 0
            1 1
            0.5 1
            0 1
          ]
        }
        coordIndex [
          0, 1, 2, 5, -1, 5, 2, 3, 4, -1
        ]
        texCoordIndex [
          5, 0, 1, 4, -1, 4, 1, 2, 3, -1
        ]
        creaseAngle 0.9
      }
    }
    Camera {
      translation 0.04 0 0.0915
      children [
        Transform {
          translation -0.015 0 0
          rotation 0 -1 0 1.57
          children [
            Shape {
              appearance PBRAppearance {
                roughness 1
                metalness 0
              }
              geometry Cylinder {
                height 0.03
                radius 0.01
              }
            }
          ]
        }
      ]
      fieldOfView 1.0472
      width 256
      height 128
      antiAliasing TRUE
      recognition Recognition {
        frameColor 0.929412 0.831373 0
        frameThickness 3
        segmentation TRUE
      }
    }
    Display {
      name "segmented image display"
      width 256
      height 128
    }
  ]
  name "MyBot"
  boundingObject Transform {
    translation 0 0 0.0415
    children [
      USE BODY
    ]
  }
  physics Physics {
    density -1
    mass 0.5
  }
  controller "camera_segmentation"
  linearVelocity 0.00018317014503412067 0.00034897748757482865 -8.402006313873124e-07
  angularVelocity 1.1730891794065426e-05 -9.920498693622091e-05 0.7549249646119788
}
