#VRML_SIM R2022a utf8
WorldInfo {
  info [
    "Example use of 'noiseMaskUrl' field of a color Camera device."
  ]
  title "Camera Noise Mask"
}
Viewpoint {
  orientation 0.19882890502343337 0.5761996650252135 -0.7927553295639295 1.1784203469785266
  position -0.6359152320709346 1.1903392717317147 1.311682171514501
}
TexturedBackground {
}
TexturedBackgroundLight {
}
RectangleArena {
}
PointLight {
  attenuation 0 0 1
  intensity 0.6
  location 0 0 0.6
}
DEF GREEN_BOX Solid {
  translation 0.25 0.05 0.05
  children [
    Shape {
      appearance PBRAppearance {
        baseColor 0 1 0
        roughness 0.2189099510000001
        metalness 0
      }
      geometry DEF BOX0 Box {
        size 0.1 0.23 0.1
      }
    }
  ]
  name "green box"
  boundingObject Shape {
    appearance PBRAppearance {
      metalness 0
    }
    geometry USE BOX0
  }
}
DEF BLUE_BOX Solid {
  translation -0.27 -0.2 0.05
  rotation 0 0 1 0.31
  children [
    Shape {
      appearance PBRAppearance {
        baseColor 0 0 1
        roughness 0.519341125
        metalness 0
      }
      geometry DEF BOX1 Box {
        size 0.1 0.2 0.1
      }
    }
  ]
  name "blue box"
  boundingObject Shape {
    appearance PBRAppearance {
      metalness 0
    }
    geometry USE BOX1
  }
}
DEF WHITE_BOX Solid {
  translation -0.15 0.2 0.05
  rotation 0 0 1 0.4
  children [
    Shape {
      appearance PBRAppearance {
        baseColor 0.74902 0.74902 0.74902
        roughness 0.10196099999999997
        metalness 0
      }
      geometry DEF BOX2 Box {
        size 0.3 0.05 0.1
      }
    }
  ]
  name "gray box"
  boundingObject Shape {
    appearance PBRAppearance {
      metalness 0
    }
    geometry USE BOX2
  }
}
DEF RED_BOX Solid {
  translation 0.1 -0.42 0.05
  rotation 0 0 1 1.8326
  children [
    Shape {
      appearance PBRAppearance {
        baseColor 1 0 0
        roughness 0.16827074099999995
        metalness 0
      }
      geometry DEF BOX3 Box {
        size 0.08 0.2 0.1
      }
    }
  ]
  name "red box"
  boundingObject Shape {
    appearance PBRAppearance {
      metalness 0
    }
    geometry USE BOX3
  }
}
Robot {
  translation -0.0017311539513640275 -0.15100656585759584 -0.0005510637499553384
  rotation 0.010647633642124503 -0.0013363503727875517 -0.999942419374988 -2.8889642596961655
  children [
    Transform {
      translation 0 0 0.0415
      rotation 0 0 1 -1.570796
      children [
        Shape {
          appearance PBRAppearance {
            baseColor 0.0820075 0.364731 0.8
            roughness 1
            metalness 0
          }
          geometry DEF BODY Cylinder {
            height 0.08
            radius 0.045
          }
        }
      ]
    }
    HingeJoint {
      jointParameters HingeJointParameters {
        position -14.450413877598379
        axis 0 1 0
        anchor 0 0 0.025
      }
      device [
        RotationalMotor {
          name "left wheel motor"
          consumptionFactor 70
        }
        PositionSensor {
          name "left wheel sensor"
        }
      ]
      endPoint Solid {
        translation 0 0.045000000000000005 0.025
        rotation 0.6610885560692715 -0.6610887156399995 -0.35485719816244593 2.4596016988158573
        children [
          DEF WHEEL Transform {
            rotation 0.577656895078166 0.5771968951617173 -0.5771968951617173 -2.093935
            children [
              Shape {
                appearance PBRAppearance {
                  baseColor 1 0 0
                  roughness 1
                  metalness 0
                }
                geometry Cylinder {
                  height 0.01
                  radius 0.025
                }
              }
            ]
          }
        ]
        name "left wheel"
        boundingObject USE WHEEL
        physics DEF PHYSICS_WHEEL Physics {
          density -1
          mass 0.05
        }
        linearVelocity 0.10824864647772044 -0.03451365523655501 -2.0247442151377512e-07
        angularVelocity 1.1977942685331808 3.8201608532924602 2.561300881786783
      }
    }
    HingeJoint {
      jointParameters HingeJointParameters {
        position 14.45040250286328
        axis 0 1 0
        anchor 0 0 0.025
      }
      device [
        RotationalMotor {
          name "right wheel motor"
          consumptionFactor 70
        }
        PositionSensor {
          name "right wheel sensor"
        }
      ]
      endPoint Solid {
        translation 0 -0.045 0.025
        rotation -0.6449436051873075 0.6449435502345667 -0.4099945891579928 2.3634075242704853
        children [
          USE WHEEL
        ]
        name "right wheel"
        boundingObject USE WHEEL
        physics USE PHYSICS_WHEEL
        linearVelocity -0.10793101016790667 0.034487804549641475 -3.533172612433707e-07
        angularVelocity -1.1967735857171136 -3.816436708886334 2.5609809471187264
      }
    }
    DistanceSensor {
      translation 0.042 0.02 0.063
      rotation 0 0 -1 -0.499205
      children [
        DEF SENSOR Transform {
          rotation 0.577656895078166 0.5771968951617173 -0.5771968951617173 -2.093935
          children [
            Shape {
              appearance PBRAppearance {
                baseColor 0.975691 0.981481 0.0252992
                roughness 1
                metalness 0
              }
              geometry Cylinder {
                height 0.004
                radius 0.008
              }
            }
          ]
        }
      ]
      name "ds0"
      lookupTable [
        0 1024 0
        0.05 1024 0
        0.15 0 0
      ]
      numberOfRays 2
      aperture 1
    }
    DistanceSensor {
      translation 0.042 -0.02 0.063
      rotation 0 0 1 -0.500795
      children [
        USE SENSOR
      ]
      name "ds1"
      lookupTable [
        0 1024 0
        0.05 1024 0
        0.15 0 0
      ]
      numberOfRays 2
      aperture 1
    }
    DEF SMILE Transform {
      translation 0.036 0 0.025
      rotation 0.25056300542381216 -0.9351130202419243 -0.25056300542381216 1.637834
      children [
        Shape {
          appearance PBRAppearance {
            baseColor 0.721569 0.290196 0.290196
            roughness 1
            metalness 0
          }
          geometry Cylinder {
            height 0.018
            radius 0.009
            subdivision 3
          }
        }
      ]
    }
    Camera {
      translation 0.04 0 0.0915
      children [
        Transform {
          translation -0.015 0 0
          rotation -0.5771968951617173 -0.577656895078166 -0.5771968951617173 -2.093935
          children [
            Shape {
              appearance PBRAppearance {
                roughness 1
                metalness 0
              }
              geometry Cylinder {
                height 0.03
                radius 0.01
              }
            }
          ]
        }
      ]
      fieldOfView 1.047
      width 400
      height 300
      antiAliasing TRUE
      noiseMaskUrl "https://raw.githubusercontent.com/cyberbotics/webots/R2022a/projects/samples/devices/worlds/textures/noise_mask.png"
    }
  ]
  name "MyBot"
  boundingObject Transform {
    translation 0 0 0.0415
    rotation 0 0 1 -1.570796
    children [
      USE BODY
    ]
  }
  physics Physics {
    density -1
    mass 0.5
  }
  controller "camera"
  linearVelocity -6.803117894098083e-05 -0.0008680866317583173 -6.005326277329423e-05
  angularVelocity 0.0004477855554187254 0.0018863314244893005 2.4886183274343487
}
