#VRML_SIM R2022a utf8
WorldInfo {
  info [
    "Example use of a color Camera device with recognition capability."
  ]
  title "Camera Image Recognition"
}
Viewpoint {
  orientation 0.45182170121048415 0.18115506182862967 -0.8735216047065633 2.662125484144553
  position 0.9124970970887923 0.3726448052237924 1.3893275356823303
}
TexturedBackground {
}
TexturedBackgroundLight {
}
RectangleArena {
}
Can {
  translation -0.267626 -0.290201 0.060961900818713485
  rotation -1.0869863196247516e-18 -3.391635334022967e-18 1 3.14159
}
Apple {
  translation 0.221872 -0.277666 0.049764745061238
  rotation 0 1 0 0
}
Apple {
  translation 0.428276 -0.291241 0.049764745061238
  rotation 0 1 0 0
  name "apple(1)"
}
JamJar {
  translation -0.314033 0.288298 0
  rotation 0 0 -1 1.0472
  mass 0
}
BiscuitBox {
  translation 0.372915 -0.247523 0.09
  rotation 0.6947461893666473 -0.1861560507404686 -0.6947471893669199 -2.773495
  size 0.17 0.33 0.04
  mass 0
}
OilBarrel {
  translation 0.122868 0.40231 0.07
  rotation 0 0 1 1.5708
  height 0.14
  radius 0.06
}
OilBarrel {
  translation 0.182198 0.278521 0.07
  rotation 0 0 1 1.5708
  name "oil barrel(1)"
  height 0.14
  radius 0.06
}
OilBarrel {
  translation 0.318097 0.364876 0.07
  rotation 0 0 1 1.5708
  name "oil barrel(2)"
  height 0.14
  radius 0.06
}
OilBarrel {
  translation 0.368241 0.196561 0.07
  rotation 0 0 1 1.5708
  name "oil barrel(3)"
  height 0.14
  radius 0.06
}
Robot {
  translation 0.000648038582262267 -0.0010387687798304353 -0.0002342236406712231
  rotation -0.01414839884191388 0.01656514930742975 0.9997626811592003 1.4140012671548254
  children [
    Transform {
      translation 0 0 0.0415
      rotation 0 0 1 -1.570796
      children [
        Shape {
          appearance PBRAppearance {
            baseColor 0.0820075 0.364731 0.8
            roughness 1
            metalness 0
          }
          geometry DEF BODY Cylinder {
            height 0.08
            radius 0.045
          }
        }
      ]
    }
    HingeJoint {
      jointParameters HingeJointParameters {
        position -5.087856662795522
        axis 0 1 0
        anchor 0 0 0.025
      }
      device [
        RotationalMotor {
          name "left wheel motor"
          consumptionFactor 70
        }
        PositionSensor {
          name "left wheel sensor"
        }
      ]
      endPoint Solid {
        translation 0 0.045000000000000005 0.025
        rotation 0.4068012056260165 -0.406801340803308 0.8179397583085507 4.512761886437464
        children [
          DEF WHEEL Transform {
            rotation 0.577656895078166 0.5771968951617173 -0.5771968951617173 -2.093935
            children [
              Shape {
                appearance PBRAppearance {
                  baseColor 1 0 0
                  roughness 1
                  metalness 0
                }
                geometry Cylinder {
                  height 0.01
                  radius 0.025
                }
              }
            ]
          }
        ]
        name "left wheel"
        boundingObject USE WHEEL
        physics DEF PHYSICS_WHEEL Physics {
          density -1
          mass 0.05
        }
        linearVelocity -0.005679831813857589 -0.033350113304558414 -1.5756119324956375e-08
        angularVelocity 1.478550436748846 -0.2533410973681142 0.7550162879895024
      }
    }
    HingeJoint {
      jointParameters HingeJointParameters {
        position 5.0878550005730405
        axis 0 1 0
        anchor 0 0 0.025
      }
      device [
        RotationalMotor {
          name "right wheel motor"
          consumptionFactor 70
        }
        PositionSensor {
          name "right wheel sensor"
        }
      ]
      endPoint Solid {
        translation 0 -0.045 0.025
        rotation -0.45430240745099376 0.4543023628808179 0.7663019546269846 4.449298539656984
        children [
          USE WHEEL
        ]
        name "right wheel"
        boundingObject USE WHEEL
        physics USE PHYSICS_WHEEL
        linearVelocity 0.005759632855397412 0.033350455219819934 3.9109552716433034e-08
        angularVelocity -1.4785487513819155 0.25333953926670416 0.7550171919120152
      }
    }
    DistanceSensor {
      translation 0.042 0.02 0.063
      rotation 0 0 -1 -0.499205
      children [
        DEF SENSOR Transform {
          rotation 0.577656895078166 0.5771968951617173 -0.5771968951617173 -2.093935
          children [
            Shape {
              appearance PBRAppearance {
                baseColor 0.975691 0.981481 0.0252992
                roughness 1
                metalness 0
              }
              geometry Cylinder {
                height 0.004
                radius 0.008
              }
            }
          ]
        }
      ]
      name "ds0"
      lookupTable [
        0 1024 0
        0.05 1024 0
        0.15 0 0
      ]
      numberOfRays 2
      aperture 1
    }
    DistanceSensor {
      translation 0.042 -0.02 0.063
      rotation 0 0 1 -0.500795
      children [
        USE SENSOR
      ]
      name "ds1"
      lookupTable [
        0 1024 0
        0.05 1024 0
        0.15 0 0
      ]
      numberOfRays 2
      aperture 1
    }
    Shape {
      appearance PBRAppearance {
        baseColor 0.8 0.8 0.8
        baseColorMap ImageTexture {
          url [
            "https://raw.githubusercontent.com/cyberbotics/webots/R2022a/projects/samples/devices/worlds/textures/mybot.png"
          ]
        }
        roughness 0.5
        metalness 0
      }
      geometry IndexedFaceSet {
        coord Coordinate {
          point [
            -0.041 0.015 0.038
            -0.041 0.015 0.023
            -0.0455 0 0.023
            -0.041 -0.015 0.023
            -0.041 -0.015 0.038
            -0.0455 0 0.038
          ]
        }
        texCoord TextureCoordinate {
          point [
            0 0
            0.5 0
            1 0
            1 1
            0.5 1
            0 1
          ]
        }
        coordIndex [
          0, 1, 2, 5, -1, 5, 2, 3, 4, -1
        ]
        texCoordIndex [
          5, 0, 1, 4, -1, 4, 1, 2, 3, -1
        ]
        creaseAngle 0.9
      }
    }
    Camera {
      translation 0.04 0 0.0915
      children [
        Transform {
          translation -0.015 0 0
          rotation -0.5771968951617173 -0.577656895078166 -0.5771968951617173 -2.093935
          children [
            Shape {
              appearance PBRAppearance {
                roughness 1
                metalness 0
              }
              geometry Cylinder {
                height 0.03
                radius 0.01
              }
            }
          ]
        }
      ]
      fieldOfView 1.0472
      width 256
      height 128
      antiAliasing TRUE
      recognition Recognition {
        frameColor 0.929412 0.831373 0
        frameThickness 3
      }
    }
  ]
  name "MyBot"
  boundingObject Transform {
    translation 0 0 0.0415
    rotation 0 0 1 -1.570796
    children [
      USE BODY
    ]
  }
  physics Physics {
    density -1
    mass 0.5
  }
  controller "camera_recognition"
  linearVelocity -0.0003061959727391112 5.928094333304646e-05 2.019141834320461e-08
  angularVelocity 8.374524589413662e-07 -7.716995700827726e-07 0.7509251764982645
}
